<sdf version='1.10'>
  <world name='empty'>
    <physics name='1ms' type='ignored'>
      <max_step_size>0.001</max_step_size>
      <real_time_factor>1</real_time_factor>
      <real_time_update_rate>1000</real_time_update_rate>
    </physics>
    <plugin name='gz::sim::systems::Physics' filename='gz-sim-physics-system'/>
    <plugin name='gz::sim::systems::UserCommands' filename='gz-sim-user-commands-system'/>
    <plugin name='gz::sim::systems::SceneBroadcaster' filename='gz-sim-scene-broadcaster-system'/>
    <plugin name='gz::sim::systems::Contact' filename='gz-sim-contact-system'/>
    <plugin
      filename="gz-sim-uwb-system"
      name="gz::sim::systems::Uwb">
    </plugin>
    <gravity>0 0 -9.8000000000000007</gravity>
    <magnetic_field>5.5644999999999998e-06 2.2875799999999999e-05 -4.2388400000000002e-05</magnetic_field>
    <atmosphere type='adiabatic'/>
    <scene>
      <ambient>0.400000006 0.400000006 0.400000006 1</ambient>
      <background>0.699999988 0.699999988 0.699999988 1</background>
      <shadows>true</shadows>
    </scene>
    <model name='ground_plane'>
      <static>true</static>
      <link name='link'>
        <collision name='collision'>
          <geometry>
            <plane>
              <normal>0 0 1</normal>
              <size>100 100</size>
            </plane>
          </geometry>
          <surface>
            <friction>
              <ode/>
            </friction>
            <bounce/>
            <contact/>
          </surface>
        </collision>
        <visual name='visual'>
          <geometry>
            <plane>
              <normal>0 0 1</normal>
              <size>100 100</size>
            </plane>
          </geometry>
          <material>
            <ambient>0.800000012 0.800000012 0.800000012 1</ambient>
            <diffuse>0.800000012 0.800000012 0.800000012 1</diffuse>
            <specular>0.800000012 0.800000012 0.800000012 1</specular>
          </material>
        </visual>
        <pose>0 0 0 0 0 0</pose>
        <inertial>
          <pose>0 0 0 0 0 0</pose>
          <mass>1</mass>
          <inertia>
            <ixx>1</ixx>
            <ixy>0</ixy>
            <ixz>0</ixz>
            <iyy>1</iyy>
            <iyz>0</iyz>
            <izz>1</izz>
          </inertia>
        </inertial>
        <enable_wind>false</enable_wind>
      </link>
      <pose>0 0 0 0 0 0</pose>
      <self_collide>false</self_collide>
    </model>
    <model name='r1_rover'>
      <link name='base_link'>
        <pose>0 0 0 0 0 0</pose>
        <inertial>
          <pose>0 0 0 0 0 0</pose>
          <mass>20</mass>
          <inertia>
            <ixx>0.37082999999999999</ixx>
            <ixy>0</ixy>
            <ixz>0</ixz>
            <iyy>0.37082999999999999</iyy>
            <iyz>0</iyz>
            <izz>0.53332999999999997</izz>
          </inertia>
        </inertial>
        <sensor name="uwb" type="uwb">
          <always_on>1</always_on>
          <update_rate>100</update_rate>
          <visualize>true</visualize>
          <topic>uwb</topic>
          <enable_metrics>true</enable_metrics>
        </sensor>
        <collision name='odom_fixed_joint_lump__base_link_collision'>
          <pose>0 0 0.14999999999999999 0 0 0</pose>
          <geometry>
            <box>
              <size>0.40000000000000002 0.40000000000000002 0.25</size>
            </box>
          </geometry>
          <surface>
            <contact>
              <ode/>
            </contact>
            <friction>
              <ode/>
            </friction>
            <bounce/>
          </surface>
        </collision>
        <visual name='odom_fixed_joint_lump__base_link_visual'>
          <pose>0 0 0 0 0 0</pose>
          <geometry>
            <mesh>
              <scale>1 1 1</scale>
              <uri>file:///home/nxpdrone/Documents/gazebo_world/r1_rover/model://r1_rover/meshes/chassis_link.STL</uri>
            </mesh>
          </geometry>
          <material>
            <script>
              <name>Gazebo/Grey</name>
              <uri>file://media/materials/scripts/gazebo.material</uri>
            </script>
          </material>
        </visual>
        <visual name='odom_fixed_joint_lump__top_link_visual_1'>
          <pose>0 0 0.114486 0 0 0</pose>
          <geometry>
            <mesh>
              <scale>1 1 1</scale>
              <uri>file:///home/nxpdrone/Documents/gazebo_world/r1_rover/model://r1_rover/meshes/top_link.STL</uri>
            </mesh>
          </geometry>
          <material>
            <script>
              <name>Gazebo/White</name>
              <uri>file://media/materials/scripts/gazebo.material</uri>
            </script>
          </material>
        </visual>
        <visual name='odom_fixed_joint_lump__battery_link_visual_2'>
          <pose>-0.093020000000000005 -0.00012799999999999999 0.114486 0 0 0</pose>
          <geometry>
            <mesh>
              <scale>1 1 1</scale>
              <uri>file:///home/nxpdrone/Documents/gazebo_world/r1_rover/model://r1_rover/meshes/battery_link.STL</uri>
            </mesh>
          </geometry>
          <material>
            <script>
              <name>Gazebo/FlatBlack</name>
              <uri>file://media/materials/scripts/gazebo.material</uri>
            </script>
          </material>
        </visual>
        <visual name='odom_fixed_joint_lump__housing_link_visual_3'>
          <pose>0.034729999999999997 0 0.114486 0 0 0</pose>
          <geometry>
            <mesh>
              <scale>1 1 1</scale>
              <uri>file:///home/nxpdrone/Documents/gazebo_world/r1_rover/model://r1_rover/meshes/housing_link.STL</uri>
            </mesh>
          </geometry>
          <material>
            <script>
              <name>Gazebo/FlatBlack</name>
              <uri>file://media/materials/scripts/gazebo.material</uri>
            </script>
          </material>
        </visual>
        <visual name='odom_fixed_joint_lump__l_antenna_link_visual_4'>
          <pose>-0.1565 0.076200000000000004 0.114486 0 0 0</pose>
          <geometry>
            <mesh>
              <scale>1 1 1</scale>
              <uri>file:///home/nxpdrone/Documents/gazebo_world/r1_rover/model://r1_rover/meshes/antenna_link.STL</uri>
            </mesh>
          </geometry>
          <material>
            <script>
              <name>Gazebo/FlatBlack</name>
              <uri>file://media/materials/scripts/gazebo.material</uri>
            </script>
          </material>
        </visual>
        <visual name='odom_fixed_joint_lump__r_antenna_link_visual_5'>
          <pose>-0.1565 -0.076200000000000004 0.114486 0 0 0</pose>
          <geometry>
            <mesh>
              <scale>1 1 1</scale>
              <uri>file:///home/nxpdrone/Documents/gazebo_world/r1_rover/model://r1_rover/meshes/antenna_link.STL</uri>
            </mesh>
          </geometry>
          <material>
            <script>
              <name>Gazebo/FlatBlack</name>
              <uri>file://media/materials/scripts/gazebo.material</uri>
            </script>
          </material>
        </visual>
        <velocity_decay/>
        <velocity_decay/>
        <velocity_decay/>
        <velocity_decay/>
        <velocity_decay/>
        <gravity>true</gravity>
        <velocity_decay/>
        <enable_wind>false</enable_wind>
      </link>
      <link name='lb_wheel_link'>
        <pose>-0.15000000000000002 0.16317000000000004 0.021499999999999998 0 0 0</pose>
        <inertial>
          <pose>0 0 0 1.57079632679 0 0</pose>
          <mass>0.41399999999999998</mass>
          <inertia>
            <ixx>0.00068681999999999999</ixx>
            <ixy>0</ixy>
            <ixz>0</ixz>
            <iyy>0.00068681999999999999</iyy>
            <iyz>0</iyz>
            <izz>0.00097298999999999997</izz>
          </inertia>
        </inertial>
        <collision name='lb_wheel_link_collision'>
          <pose>0 0 0 1.57079632679 0 0</pose>
          <geometry>
            <cylinder>
              <radius>0.068599999999999994</radius>
              <length>0.076200000000000004</length>
            </cylinder>
          </geometry>
          <max_contacts>1</max_contacts>
          <surface>
            <friction>
              <torsional>
                <coefficient>0.25</coefficient>
                <use_patch_radius>true</use_patch_radius>
                <surface_radius>0.068599999999999994</surface_radius>
              </torsional>
              <ode>
                <mu>1</mu>
                <mu2>0.45000000000000001</mu2>
                <fdir1>1 0 0</fdir1>
                <slip1>0</slip1>
                <slip2>0</slip2>
              </ode>
            </friction>
            <bounce>
              <restitution_coefficient>0</restitution_coefficient>
              <threshold>1000000</threshold>
            </bounce>
            <contact>
              <ode>
                <min_depth>0.001</min_depth>
                <max_vel>0</max_vel>
                <kp>1000000</kp>
                <kd>100</kd>
              </ode>
            </contact>
          </surface>
        </collision>
        <visual name='lb_wheel_link_visual'>
          <pose>0 0 0 0 0 0</pose>
          <geometry>
            <mesh>
              <scale>1 1 1</scale>
              <uri>file:///home/nxpdrone/Documents/gazebo_world/r1_rover/model://r1_rover/meshes/wheel_link.STL</uri>
            </mesh>
          </geometry>
          <material>
            <script>
              <name>Gazebo/FlatBlack</name>
              <uri>file://media/materials/scripts/gazebo.material</uri>
            </script>
          </material>
        </visual>
        <gravity>true</gravity>
        <velocity_decay/>
        <enable_wind>false</enable_wind>
      </link>
      <joint name='lb_wheel_joint' type='revolute'>
        <child>lb_wheel_link</child>
        <parent>base_link</parent>
        <axis>
          <xyz>0 1 0</xyz>
          <limit>
            <lower>-10000000000000000</lower>
            <upper>10000000000000000</upper>
            <effort>inf</effort>
            <velocity>inf</velocity>
            <stiffness>100000000</stiffness>
            <dissipation>1</dissipation>
          </limit>
          <dynamics>
            <spring_reference>0</spring_reference>
            <spring_stiffness>0</spring_stiffness>
            <damping>0</damping>
            <friction>0</friction>
          </dynamics>
        </axis>
        <pose>0 0 0 0 0 0</pose>
      </joint>
      <link name='lf_wheel_link'>
        <pose>0.14999999999999999 0.16317000000000004 0.021499999999999998 0 0 0</pose>
        <inertial>
          <pose>0 0 0 1.57079632679 0 0</pose>
          <mass>0.41399999999999998</mass>
          <inertia>
            <ixx>0.00068681999999999999</ixx>
            <ixy>0</ixy>
            <ixz>0</ixz>
            <iyy>0.00068681999999999999</iyy>
            <iyz>0</iyz>
            <izz>0.00097298999999999997</izz>
          </inertia>
        </inertial>
        <collision name='lf_wheel_link_collision'>
          <pose>0 0 0 1.57079632679 0 0</pose>
          <geometry>
            <cylinder>
              <radius>0.068599999999999994</radius>
              <length>0.076200000000000004</length>
            </cylinder>
          </geometry>
          <max_contacts>1</max_contacts>
          <surface>
            <friction>
              <torsional>
                <coefficient>0.25</coefficient>
                <use_patch_radius>true</use_patch_radius>
                <surface_radius>0.068599999999999994</surface_radius>
              </torsional>
              <ode>
                <mu>1</mu>
                <mu2>0.45000000000000001</mu2>
                <fdir1>1 0 0</fdir1>
                <slip1>0</slip1>
                <slip2>0</slip2>
              </ode>
            </friction>
            <bounce>
              <restitution_coefficient>0</restitution_coefficient>
              <threshold>1000000</threshold>
            </bounce>
            <contact>
              <ode>
                <min_depth>0.001</min_depth>
                <max_vel>0</max_vel>
                <kp>1000000</kp>
                <kd>100</kd>
              </ode>
            </contact>
          </surface>
        </collision>
        <visual name='lf_wheel_link_visual'>
          <pose>0 0 0 0 0 0</pose>
          <geometry>
            <mesh>
              <scale>1 1 1</scale>
              <uri>file:///home/nxpdrone/Documents/gazebo_world/r1_rover/model://r1_rover/meshes/wheel_link.STL</uri>
            </mesh>
          </geometry>
          <material>
            <script>
              <name>Gazebo/FlatBlack</name>
              <uri>file://media/materials/scripts/gazebo.material</uri>
            </script>
          </material>
        </visual>
        <gravity>true</gravity>
        <velocity_decay/>
        <enable_wind>false</enable_wind>
      </link>
      <joint name='lf_wheel_joint' type='revolute'>
        <child>lf_wheel_link</child>
        <parent>base_link</parent>
        <axis>
          <xyz>0 1 0</xyz>
          <limit>
            <lower>-10000000000000000</lower>
            <upper>10000000000000000</upper>
            <effort>inf</effort>
            <velocity>inf</velocity>
            <stiffness>100000000</stiffness>
            <dissipation>1</dissipation>
          </limit>
          <dynamics>
            <spring_reference>0</spring_reference>
            <spring_stiffness>0</spring_stiffness>
            <damping>0</damping>
            <friction>0</friction>
          </dynamics>
        </axis>
        <pose>0 0 0 0 0 0</pose>
      </joint>
      <link name='rb_wheel_link'>
        <pose>-0.15000000000000002 -0.16317000000000004 0.021499999999999998 0 0 0</pose>
        <inertial>
          <pose>0 0 0 1.57079632679 0 0</pose>
          <mass>0.41399999999999998</mass>
          <inertia>
            <ixx>0.00068681999999999999</ixx>
            <ixy>0</ixy>
            <ixz>0</ixz>
            <iyy>0.00068681999999999999</iyy>
            <iyz>0</iyz>
            <izz>0.00097298999999999997</izz>
          </inertia>
        </inertial>
        <collision name='rb_wheel_link_collision'>
          <pose>0 0 0 1.57079632679 0 0</pose>
          <geometry>
            <cylinder>
              <radius>0.068599999999999994</radius>
              <length>0.076200000000000004</length>
            </cylinder>
          </geometry>
          <max_contacts>1</max_contacts>
          <surface>
            <friction>
              <torsional>
                <coefficient>0.25</coefficient>
                <use_patch_radius>true</use_patch_radius>
                <surface_radius>0.068599999999999994</surface_radius>
              </torsional>
              <ode>
                <mu>1</mu>
                <mu2>0.45000000000000001</mu2>
                <fdir1>1 0 0</fdir1>
                <slip1>0</slip1>
                <slip2>0</slip2>
              </ode>
            </friction>
            <bounce>
              <restitution_coefficient>0</restitution_coefficient>
              <threshold>1000000</threshold>
            </bounce>
            <contact>
              <ode>
                <min_depth>0.001</min_depth>
                <kp>100000000</kp>
              </ode>
            </contact>
          </surface>
        </collision>
        <visual name='rb_wheel_link_visual'>
          <pose>0 0 0 0 0 0</pose>
          <geometry>
            <mesh>
              <scale>1 1 1</scale>
              <uri>file:///home/nxpdrone/Documents/gazebo_world/r1_rover/model://r1_rover/meshes/wheel_link.STL</uri>
            </mesh>
          </geometry>
          <material>
            <script>
              <name>Gazebo/FlatBlack</name>
              <uri>file://media/materials/scripts/gazebo.material</uri>
            </script>
          </material>
        </visual>
        <gravity>true</gravity>
        <velocity_decay/>
        <enable_wind>false</enable_wind>
      </link>
      <joint name='rb_wheel_joint' type='revolute'>
        <child>rb_wheel_link</child>
        <parent>base_link</parent>
        <axis>
          <xyz>0 1 0</xyz>
          <limit>
            <lower>-10000000000000000</lower>
            <upper>10000000000000000</upper>
            <effort>inf</effort>
            <velocity>inf</velocity>
            <stiffness>100000000</stiffness>
            <dissipation>1</dissipation>
          </limit>
          <dynamics>
            <spring_reference>0</spring_reference>
            <spring_stiffness>0</spring_stiffness>
            <damping>0</damping>
            <friction>0</friction>
          </dynamics>
        </axis>
        <pose>0 0 0 0 0 0</pose>
      </joint>
      <link name='rf_wheel_link'>
        <pose>0.14999999999999999 -0.16317000000000004 0.021499999999999998 0 0 0</pose>
        <inertial>
          <pose>0 0 0 1.57079632679 0 0</pose>
          <mass>0.41399999999999998</mass>
          <inertia>
            <ixx>0.00068681999999999999</ixx>
            <ixy>0</ixy>
            <ixz>0</ixz>
            <iyy>0.00068681999999999999</iyy>
            <iyz>0</iyz>
            <izz>0.00097298999999999997</izz>
          </inertia>
        </inertial>
        <collision name='rf_wheel_link_collision'>
          <pose>0 0 0 1.57079632679 0 0</pose>
          <geometry>
            <cylinder>
              <radius>0.068599999999999994</radius>
              <length>0.076200000000000004</length>
            </cylinder>
          </geometry>
          <max_contacts>1</max_contacts>
          <surface>
            <friction>
              <torsional>
                <coefficient>0.25</coefficient>
                <use_patch_radius>true</use_patch_radius>
                <surface_radius>0.068599999999999994</surface_radius>
              </torsional>
              <ode>
                <mu>1</mu>
                <mu2>0.45000000000000001</mu2>
                <fdir1>1 0 0</fdir1>
                <slip1>0</slip1>
                <slip2>0</slip2>
              </ode>
            </friction>
            <bounce>
              <restitution_coefficient>0</restitution_coefficient>
              <threshold>1000000</threshold>
            </bounce>
            <contact>
              <ode>
                <min_depth>0.001</min_depth>
                <max_vel>0</max_vel>
                <kp>1000000</kp>
                <kd>100</kd>
              </ode>
            </contact>
          </surface>
        </collision>
        <visual name='rf_wheel_link_visual'>
          <pose>0 0 0 0 0 0</pose>
          <geometry>
            <mesh>
              <scale>1 1 1</scale>
              <uri>file:///home/nxpdrone/Documents/gazebo_world/r1_rover/model://r1_rover/meshes/wheel_link.STL</uri>
            </mesh>
          </geometry>
          <material>
            <script>
              <name>Gazebo/FlatBlack</name>
              <uri>file://media/materials/scripts/gazebo.material</uri>
            </script>
          </material>
        </visual>
        <gravity>true</gravity>
        <velocity_decay/>
        <enable_wind>false</enable_wind>
      </link>
      <joint name='rf_wheel_joint' type='revolute'>
        <child>rf_wheel_link</child>
        <parent>base_link</parent>
        <axis>
          <xyz>0 1 0</xyz>
          <limit>
            <lower>-10000000000000000</lower>
            <upper>10000000000000000</upper>
            <effort>inf</effort>
            <velocity>inf</velocity>
            <stiffness>100000000</stiffness>
            <dissipation>1</dissipation>
          </limit>
          <dynamics>
            <spring_reference>0</spring_reference>
            <spring_stiffness>0</spring_stiffness>
            <damping>0</damping>
            <friction>0</friction>
          </dynamics>
        </axis>
        <pose>0 0 0 0 0 0</pose>
      </joint>
      <static>false</static>
      <plugin name='mavlink_interface' filename='libgazebo_mavlink_interface.so'>
        <robotNamespace/>
        <imuSubTopic>/imu</imuSubTopic>
        <magSubTopic>/mag</magSubTopic>
        <baroSubTopic>/baro</baroSubTopic>
        <mavlink_addr>INADDR_ANY</mavlink_addr>
        <mavlink_tcp_port>{{ mavlink_tcp_port }}</mavlink_tcp_port>
        <mavlink_udp_port>{{ mavlink_udp_port }}</mavlink_udp_port>
        <serialEnabled>false</serialEnabled>
        <serialDevice>/dev/ttyACM0</serialDevice>
        <baudRate>921600</baudRate>
        <qgc_addr>INADDR_ANY</qgc_addr>
        <qgc_udp_port>14550</qgc_udp_port>
        <sdk_addr>INADDR_ANY</sdk_addr>
        <sdk_udp_port>14540</sdk_udp_port>
        <hil_mode>false</hil_mode>
        <hil_state_level>false</hil_state_level>
        <enable_lockstep>true</enable_lockstep>
        <use_tcp>true</use_tcp>
        <motorSpeedCommandPubTopic>/gazebo/command/motor_speed</motorSpeedCommandPubTopic>
        <control_channels>
          <channel name='left_front_wheel_drive'>
            <input_index>0</input_index>
            <input_offset>0</input_offset>
            <input_scaling>40</input_scaling>
            <zero_position_disarmed>0</zero_position_disarmed>
            <zero_position_armed>0</zero_position_armed>
            <joint_control_type>velocity</joint_control_type>
            <joint_name>lf_wheel_joint</joint_name>
            <joint_control_pid>
              <p>0.1</p>
              <i>0</i>
              <d>0</d>
              <iMax>800</iMax>
              <iMin>-800</iMin>
              <cmdMax>1200</cmdMax>
              <cmdMin>-1200</cmdMin>
            </joint_control_pid>
          </channel>
          <channel name='left_back_wheel_drive'>
            <input_index>1</input_index>
            <input_offset>0</input_offset>
            <input_scaling>40</input_scaling>
            <zero_position_disarmed>0</zero_position_disarmed>
            <zero_position_armed>0</zero_position_armed>
            <joint_control_type>velocity</joint_control_type>
            <joint_name>lb_wheel_joint</joint_name>
            <joint_control_pid>
              <p>0.1</p>
              <i>0</i>
              <d>0</d>
              <iMax>800</iMax>
              <iMin>-800</iMin>
              <cmdMax>1200</cmdMax>
              <cmdMin>-1200</cmdMin>
            </joint_control_pid>
          </channel>
          <channel name='right_front_wheel_drive'>
            <input_index>5</input_index>
            <input_offset>0</input_offset>
            <input_scaling>40</input_scaling>
            <zero_position_disarmed>0</zero_position_disarmed>
            <zero_position_armed>0</zero_position_armed>
            <joint_control_type>velocity</joint_control_type>
            <joint_name>rf_wheel_joint</joint_name>
            <joint_control_pid>
              <p>0.1</p>
              <i>0</i>
              <d>0</d>
              <iMax>800</iMax>
              <iMin>-800</iMin>
              <cmdMax>1200</cmdMax>
              <cmdMin>-1200</cmdMin>
            </joint_control_pid>
          </channel>
          <channel name='right_back_wheel_drive'>
            <input_index>6</input_index>
            <input_offset>0</input_offset>
            <input_scaling>40</input_scaling>
            <zero_position_disarmed>0</zero_position_disarmed>
            <zero_position_armed>0</zero_position_armed>
            <joint_control_type>velocity</joint_control_type>
            <joint_name>rb_wheel_joint</joint_name>
            <joint_control_pid>
              <p>0.1</p>
              <i>0</i>
              <d>0</d>
              <iMax>800</iMax>
              <iMin>-800</iMin>
              <cmdMax>1200</cmdMax>
              <cmdMin>-1200</cmdMin>
            </joint_control_pid>
          </channel>
        </control_channels>
      </plugin>
      <pose>-0.19909518465943066 -0.75395962529422045 0 0 0 0</pose>
      <self_collide>false</self_collide>
    </model>
    <model name='x500-Base'>
      <pose>-1.6554419712450841 -0.95230346010472799 0.23999999999999999 0 0 0</pose>
      <self_collide>false</self_collide>
      <static>false</static>
      <link name='base_link'>
        <inertial>
          <mass>2</mass>
          <inertia>
            <ixx>0.021666666666666671</ixx>
            <ixy>0</ixy>
            <ixz>0</ixz>
            <iyy>0.021666666666666671</iyy>
            <iyz>0</iyz>
            <izz>0.040000000000000008</izz>
          </inertia>
          <pose>0 0 0 0 0 0</pose>
        </inertial>
        <gravity>true</gravity>
        <velocity_decay/>
        <sensor name="uwb" type="uwb">
          <always_on>1</always_on>
          <update_rate>100</update_rate>
          <visualize>true</visualize>
          <topic>uwb</topic>
          <enable_metrics>true</enable_metrics>
        </sensor>
        <visual name='base_link_visual'>
          <pose>0 0 0.025000000000000001 0 0 -3.1415926531795866</pose>
          <geometry>
            <mesh>
              <scale>1 1 1</scale>
              <uri>file:///home/nxpdrone/Documents/gazebo_world/x500-Base/model://x500-Base/meshes/NXP-HGD-CF.dae</uri>
            </mesh>
          </geometry>
        </visual>
        <visual name='5010_motor_base_0'>
          <pose>0.17399999999999999 0.17399999999999999 0.032000000000000001 0 0 -0.45000000000000001</pose>
          <geometry>
            <mesh>
              <scale>1 1 1</scale>
              <uri>file:///home/nxpdrone/Documents/gazebo_world/x500-Base/model://x500-Base/meshes/5010Base.dae</uri>
            </mesh>
          </geometry>
        </visual>
        <visual name='5010_motor_base_1'>
          <pose>-0.17399999999999999 0.17399999999999999 0.032000000000000001 0 0 -0.45000000000000001</pose>
          <geometry>
            <mesh>
              <scale>1 1 1</scale>
              <uri>file:///home/nxpdrone/Documents/gazebo_world/x500-Base/model://x500-Base/meshes/5010Base.dae</uri>
            </mesh>
          </geometry>
        </visual>
        <visual name='5010_motor_base_2'>
          <pose>0.17399999999999999 -0.17399999999999999 0.032000000000000001 0 0 -0.45000000000000001</pose>
          <geometry>
            <mesh>
              <scale>1 1 1</scale>
              <uri>file:///home/nxpdrone/Documents/gazebo_world/x500-Base/model://x500-Base/meshes/5010Base.dae</uri>
            </mesh>
          </geometry>
        </visual>
        <visual name='5010_motor_base_3'>
          <pose>-0.17399999999999999 -0.17399999999999999 0.032000000000000001 0 0 -0.45000000000000001</pose>
          <geometry>
            <mesh>
              <scale>1 1 1</scale>
              <uri>file:///home/nxpdrone/Documents/gazebo_world/x500-Base/model://x500-Base/meshes/5010Base.dae</uri>
            </mesh>
          </geometry>
        </visual>
        <visual name='NXP_FMUK66_FRONT'>
          <pose>0.047 0.001 0.042999999999999997 1 1.1102230246251565e-16 1.5699999999999998</pose>
          <cast_shadows>false</cast_shadows>
          <geometry>
            <plane>
              <normal>0 0 1</normal>
              <size>0.012999999999999999 0.0070000000000000001</size>
            </plane>
          </geometry>
          <material>
            <diffuse>1 1 1 1</diffuse>
            <specular>1 1 1 1</specular>
            <pbr>
              <metal>
                <albedo_map>model://x500-Base/materials/textures/nxp.png</albedo_map>
              </metal>
            </pbr>
          </material>
        </visual>
        <visual name='NXP_FMUK66_TOP'>
          <pose>-0.023 0 0.051499999999999997 0 0 -1.5700000000000001</pose>
          <cast_shadows>false</cast_shadows>
          <geometry>
            <plane>
              <normal>0 0 1</normal>
              <size>0.012999999999999999 0.0070000000000000001</size>
            </plane>
          </geometry>
          <material>
            <diffuse>1 1 1 1</diffuse>
            <specular>1 1 1 1</specular>
            <pbr>
              <metal>
                <albedo_map>model://x500-Base/materials/textures/nxp.png</albedo_map>
              </metal>
            </pbr>
          </material>
        </visual>
        <visual name='RDDRONE_FMUK66_TOP'>
          <pose>-0.029999999999999999 0 0.051499999999999997 0 0 -1.5700000000000001</pose>
          <cast_shadows>false</cast_shadows>
          <geometry>
            <plane>
              <normal>0 0 1</normal>
              <size>0.032000000000000001 0.0033999999999999998</size>
            </plane>
          </geometry>
          <material>
            <diffuse>1 1 1 1</diffuse>
            <specular>1 1 1 1</specular>
            <pbr>
              <metal>
                <albedo_map>model://x500-Base/materials/textures/rd.png</albedo_map>
              </metal>
            </pbr>
          </material>
        </visual>
        <collision name='base_link_collision_0'>
          <pose>0 0 0.0070000000000000001 0 0 0</pose>
          <geometry>
            <box>
              <size>0.35355339059327373 0.35355339059327373 0.050000000000000003</size>
            </box>
          </geometry>
          <surface>
            <contact>
              <ode>
                <min_depth>0.001</min_depth>
                <max_vel>0</max_vel>
              </ode>
            </contact>
            <friction>
              <ode/>
            </friction>
            <bounce/>
          </surface>
        </collision>
        <collision name='base_link_collision_1'>
          <pose>0 -0.098000000000000004 -0.123 -0.34999999999999998 0 0</pose>
          <geometry>
            <box>
              <size>0.014999999999999999 0.014999999999999999 0.20999999999999999</size>
            </box>
          </geometry>
          <surface>
            <contact>
              <ode>
                <min_depth>0.001</min_depth>
                <max_vel>0</max_vel>
              </ode>
            </contact>
            <friction>
              <ode/>
            </friction>
            <bounce/>
          </surface>
        </collision>
        <collision name='base_link_collision_2'>
          <pose>0 0.098000000000000004 -0.123 0.34999999999999998 0 0</pose>
          <geometry>
            <box>
              <size>0.014999999999999999 0.014999999999999999 0.20999999999999999</size>
            </box>
          </geometry>
          <surface>
            <contact>
              <ode>
                <min_depth>0.001</min_depth>
                <max_vel>0</max_vel>
              </ode>
            </contact>
            <friction>
              <ode/>
            </friction>
            <bounce/>
          </surface>
        </collision>
        <collision name='base_link_collision_3'>
          <pose>0 -0.13200000000000001 -0.2195 0 0 0</pose>
          <geometry>
            <box>
              <size>0.25 0.014999999999999999 0.014999999999999999</size>
            </box>
          </geometry>
          <surface>
            <contact>
              <ode>
                <min_depth>0.001</min_depth>
                <max_vel>0</max_vel>
              </ode>
            </contact>
            <friction>
              <ode/>
            </friction>
            <bounce/>
          </surface>
        </collision>
        <collision name='base_link_collision_4'>
          <pose>0 0.13200000000000001 -0.2195 0 0 0</pose>
          <geometry>
            <box>
              <size>0.25 0.014999999999999999 0.014999999999999999</size>
            </box>
          </geometry>
          <surface>
            <contact>
              <ode>
                <min_depth>0.001</min_depth>
                <max_vel>0</max_vel>
              </ode>
            </contact>
            <friction>
              <ode/>
            </friction>
            <bounce/>
          </surface>
        </collision>
        <sensor name='imu_sensor' type='imu'>
          <pose>0 0 0 0 0 0</pose>
          <topic>__default__</topic>
          <update_rate>250</update_rate>
          <enable_metrics>false</enable_metrics>
          <imu>
            <orientation_reference_frame>
              <localization>CUSTOM</localization>
              <custom_rpy>0 0 0</custom_rpy>
              <grav_dir_x>1 0 0</grav_dir_x>
            </orientation_reference_frame>
            <angular_velocity>
              <x>
                <noise type='none'>
                  <mean>0</mean>
                  <stddev>0</stddev>
                  <bias_mean>0</bias_mean>
                  <bias_stddev>0</bias_stddev>
                  <dynamic_bias_stddev>0</dynamic_bias_stddev>
                  <dynamic_bias_correlation_time>0</dynamic_bias_correlation_time>
                  <precision>0</precision>
                </noise>
              </x>
              <y>
                <noise type='none'>
                  <mean>0</mean>
                  <stddev>0</stddev>
                  <bias_mean>0</bias_mean>
                  <bias_stddev>0</bias_stddev>
                  <dynamic_bias_stddev>0</dynamic_bias_stddev>
                  <dynamic_bias_correlation_time>0</dynamic_bias_correlation_time>
                  <precision>0</precision>
                </noise>
              </y>
              <z>
                <noise type='none'>
                  <mean>0</mean>
                  <stddev>0</stddev>
                  <bias_mean>0</bias_mean>
                  <bias_stddev>0</bias_stddev>
                  <dynamic_bias_stddev>0</dynamic_bias_stddev>
                  <dynamic_bias_correlation_time>0</dynamic_bias_correlation_time>
                  <precision>0</precision>
                </noise>
              </z>
            </angular_velocity>
            <linear_acceleration>
              <x>
                <noise type='none'>
                  <mean>0</mean>
                  <stddev>0</stddev>
                  <bias_mean>0</bias_mean>
                  <bias_stddev>0</bias_stddev>
                  <dynamic_bias_stddev>0</dynamic_bias_stddev>
                  <dynamic_bias_correlation_time>0</dynamic_bias_correlation_time>
                  <precision>0</precision>
                </noise>
              </x>
              <y>
                <noise type='none'>
                  <mean>0</mean>
                  <stddev>0</stddev>
                  <bias_mean>0</bias_mean>
                  <bias_stddev>0</bias_stddev>
                  <dynamic_bias_stddev>0</dynamic_bias_stddev>
                  <dynamic_bias_correlation_time>0</dynamic_bias_correlation_time>
                  <precision>0</precision>
                </noise>
              </y>
              <z>
                <noise type='none'>
                  <mean>0</mean>
                  <stddev>0</stddev>
                  <bias_mean>0</bias_mean>
                  <bias_stddev>0</bias_stddev>
                  <dynamic_bias_stddev>0</dynamic_bias_stddev>
                  <dynamic_bias_correlation_time>0</dynamic_bias_correlation_time>
                  <precision>0</precision>
                </noise>
              </z>
            </linear_acceleration>
            <enable_orientation>true</enable_orientation>
          </imu>
        </sensor>
        <pose>0 0 0 0 0 0</pose>
        <enable_wind>false</enable_wind>
      </link>
      <link name='rotor_0'>
        <gravity>true</gravity>
        <self_collide>false</self_collide>
        <velocity_decay/>
        <pose>0.17399999999999993 -0.17399999999999993 0.059999999999999998 0 0 0</pose>
        <inertial>
          <mass>0.016076923076923075</mass>
          <inertia>
            <ixx>3.8464910483993325e-07</ixx>
            <iyy>2.6115851691700804e-05</iyy>
            <izz>2.6498582347140039e-05</izz>
            <ixy>0</ixy>
            <ixz>0</ixz>
            <iyz>0</iyz>
          </inertia>
          <pose>0 0 0 0 0 0</pose>
        </inertial>
        <visual name='rotor_0_visual'>
          <pose>-0.021999999999999999 -0.14638461538461536 -0.016 0 0 0</pose>
          <geometry>
            <mesh>
              <scale>0.84615384615384615 0.84615384615384615 0.84615384615384615</scale>
              <uri>file:///home/nxpdrone/Documents/gazebo_world/x500-Base/model://x500-Base/meshes/1345_prop_ccw.stl</uri>
            </mesh>
          </geometry>
          <material>
            <script>
              <name>Gazebo/DarkGrey</name>
              <uri>file://media/materials/scripts/gazebo.material</uri>
            </script>
          </material>
        </visual>
        <visual name='rotor_0_visual_motor_bell'>
          <pose>0 0 -0.032000000000000001 0 0 0</pose>
          <geometry>
            <mesh>
              <scale>1 1 1</scale>
              <uri>file:///home/nxpdrone/Documents/gazebo_world/x500-Base/model://x500-Base/meshes/5010Bell.dae</uri>
            </mesh>
          </geometry>
        </visual>
        <collision name='rotor_0_collision'>
          <pose>0 0 0 0 0 0</pose>
          <geometry>
            <box>
              <size>0.27923076923076923 0.016923076923076923 0.0008461538461538462</size>
            </box>
          </geometry>
          <surface>
            <contact>
              <ode>
                <min_depth>0.001</min_depth>
                <max_vel>0</max_vel>
              </ode>
            </contact>
            <friction>
              <ode/>
            </friction>
            <bounce/>
          </surface>
        </collision>
        <enable_wind>false</enable_wind>
      </link>
      <joint name='rotor_0_joint' type='revolute'>
        <parent>base_link</parent>
        <child>rotor_0</child>
        <axis>
          <xyz>0 0 1</xyz>
          <limit>
            <lower>-10000000000000000</lower>
            <upper>10000000000000000</upper>
            <effort>inf</effort>
            <velocity>inf</velocity>
            <stiffness>100000000</stiffness>
            <dissipation>1</dissipation>
          </limit>
          <dynamics>
            <spring_reference>0</spring_reference>
            <spring_stiffness>0</spring_stiffness>
            <damping>0</damping>
            <friction>0</friction>
          </dynamics>
        </axis>
        <pose>0 0 0 0 0 0</pose>
      </joint>
      <link name='rotor_1'>
        <gravity>true</gravity>
        <self_collide>false</self_collide>
        <velocity_decay/>
        <pose>-0.17399999999999993 0.17399999999999993 0.059999999999999998 0 0 0</pose>
        <inertial>
          <mass>0.016076923076923075</mass>
          <inertia>
            <ixx>3.8464910483993325e-07</ixx>
            <iyy>2.6115851691700804e-05</iyy>
            <izz>2.6498582347140039e-05</izz>
            <ixy>0</ixy>
            <ixz>0</ixz>
            <iyz>0</iyz>
          </inertia>
          <pose>0 0 0 0 0 0</pose>
        </inertial>
        <visual name='rotor_1_visual'>
          <pose>-0.021999999999999999 -0.14638461538461536 -0.016 0 0 0</pose>
          <geometry>
            <mesh>
              <scale>0.84615384615384615 0.84615384615384615 0.84615384615384615</scale>
              <uri>file:///home/nxpdrone/Documents/gazebo_world/x500-Base/model://x500-Base/meshes/1345_prop_ccw.stl</uri>
            </mesh>
          </geometry>
          <material>
            <script>
              <name>Gazebo/DarkGrey</name>
              <uri>file://media/materials/scripts/gazebo.material</uri>
            </script>
          </material>
        </visual>
        <visual name='rotor_1_visual_motor_top'>
          <pose>0 0 -0.032000000000000001 0 0 0</pose>
          <geometry>
            <mesh>
              <scale>1 1 1</scale>
              <uri>file:///home/nxpdrone/Documents/gazebo_world/x500-Base/model://x500-Base/meshes/5010Bell.dae</uri>
            </mesh>
          </geometry>
        </visual>
        <collision name='rotor_1_collision'>
          <pose>0 0 0 0 0 0</pose>
          <geometry>
            <box>
              <size>0.27923076923076923 0.016923076923076923 0.0008461538461538462</size>
            </box>
          </geometry>
          <surface>
            <contact>
              <ode>
                <min_depth>0.001</min_depth>
                <max_vel>0</max_vel>
              </ode>
            </contact>
            <friction>
              <ode/>
            </friction>
            <bounce/>
          </surface>
        </collision>
        <enable_wind>false</enable_wind>
      </link>
      <joint name='rotor_1_joint' type='revolute'>
        <parent>base_link</parent>
        <child>rotor_1</child>
        <axis>
          <xyz>0 0 1</xyz>
          <limit>
            <lower>-10000000000000000</lower>
            <upper>10000000000000000</upper>
            <effort>inf</effort>
            <velocity>inf</velocity>
            <stiffness>100000000</stiffness>
            <dissipation>1</dissipation>
          </limit>
          <dynamics>
            <spring_reference>0</spring_reference>
            <spring_stiffness>0</spring_stiffness>
            <damping>0</damping>
            <friction>0</friction>
          </dynamics>
        </axis>
        <pose>0 0 0 0 0 0</pose>
      </joint>
      <link name='rotor_2'>
        <gravity>true</gravity>
        <self_collide>false</self_collide>
        <velocity_decay/>
        <pose>0.17399999999999993 0.17399999999999993 0.059999999999999998 0 0 0</pose>
        <inertial>
          <mass>0.016076923076923075</mass>
          <inertia>
            <ixx>3.8464910483993325e-07</ixx>
            <iyy>2.6115851691700804e-05</iyy>
            <izz>2.6498582347140039e-05</izz>
            <ixy>0</ixy>
            <ixz>0</ixz>
            <iyz>0</iyz>
          </inertia>
          <pose>0 0 0 0 0 0</pose>
        </inertial>
        <visual name='rotor_2_visual'>
          <pose>-0.021999999999999999 -0.14638461538461536 -0.016 0 0 0</pose>
          <geometry>
            <mesh>
              <scale>0.84615384615384615 0.84615384615384615 0.84615384615384615</scale>
              <uri>file:///home/nxpdrone/Documents/gazebo_world/x500-Base/model://x500-Base/meshes/1345_prop_cw.stl</uri>
            </mesh>
          </geometry>
          <material>
            <script>
              <name>Gazebo/DarkGrey</name>
              <uri>file://media/materials/scripts/gazebo.material</uri>
            </script>
          </material>
        </visual>
        <visual name='rotor_2_visual_motor_top'>
          <pose>0 0 -0.032000000000000001 0 0 0</pose>
          <geometry>
            <mesh>
              <scale>1 1 1</scale>
              <uri>file:///home/nxpdrone/Documents/gazebo_world/x500-Base/model://x500-Base/meshes/5010Bell.dae</uri>
            </mesh>
          </geometry>
        </visual>
        <collision name='rotor_2_collision'>
          <pose>0 0 0 0 0 0</pose>
          <geometry>
            <box>
              <size>0.27923076923076923 0.016923076923076923 0.0008461538461538462</size>
            </box>
          </geometry>
          <surface>
            <contact>
              <ode>
                <min_depth>0.001</min_depth>
                <max_vel>0</max_vel>
              </ode>
            </contact>
            <friction>
              <ode/>
            </friction>
            <bounce/>
          </surface>
        </collision>
        <enable_wind>false</enable_wind>
      </link>
      <joint name='rotor_2_joint' type='revolute'>
        <parent>base_link</parent>
        <child>rotor_2</child>
        <axis>
          <xyz>0 0 1</xyz>
          <limit>
            <lower>-10000000000000000</lower>
            <upper>10000000000000000</upper>
            <effort>inf</effort>
            <velocity>inf</velocity>
            <stiffness>100000000</stiffness>
            <dissipation>1</dissipation>
          </limit>
          <dynamics>
            <spring_reference>0</spring_reference>
            <spring_stiffness>0</spring_stiffness>
            <damping>0</damping>
            <friction>0</friction>
          </dynamics>
        </axis>
        <pose>0 0 0 0 0 0</pose>
      </joint>
      <link name='rotor_3'>
        <gravity>true</gravity>
        <self_collide>false</self_collide>
        <velocity_decay/>
        <pose>-0.17399999999999993 -0.17399999999999993 0.059999999999999998 0 0 0</pose>
        <inertial>
          <mass>0.016076923076923075</mass>
          <inertia>
            <ixx>3.8464910483993325e-07</ixx>
            <iyy>2.6115851691700804e-05</iyy>
            <izz>2.6498582347140039e-05</izz>
            <ixy>0</ixy>
            <ixz>0</ixz>
            <iyz>0</iyz>
          </inertia>
          <pose>0 0 0 0 0 0</pose>
        </inertial>
        <visual name='rotor_3_visual'>
          <pose>-0.021999999999999999 -0.14638461538461536 -0.016 0 0 0</pose>
          <geometry>
            <mesh>
              <scale>0.84615384615384615 0.84615384615384615 0.84615384615384615</scale>
              <uri>file:///home/nxpdrone/Documents/gazebo_world/x500-Base/model://x500-Base/meshes/1345_prop_cw.stl</uri>
            </mesh>
          </geometry>
          <material>
            <script>
              <name>Gazebo/DarkGrey</name>
              <uri>file://media/materials/scripts/gazebo.material</uri>
            </script>
          </material>
        </visual>
        <visual name='rotor_3_visual_motor_top'>
          <pose>0 0 -0.032000000000000001 0 0 0</pose>
          <geometry>
            <mesh>
              <scale>1 1 1</scale>
              <uri>file:///home/nxpdrone/Documents/gazebo_world/x500-Base/model://x500-Base/meshes/5010Bell.dae</uri>
            </mesh>
          </geometry>
        </visual>
        <collision name='rotor_3_collision'>
          <pose>0 0 0 0 0 0</pose>
          <geometry>
            <box>
              <size>0.27923076923076923 0.016923076923076923 0.0008461538461538462</size>
            </box>
          </geometry>
          <surface>
            <contact>
              <ode>
                <min_depth>0.001</min_depth>
                <max_vel>0</max_vel>
              </ode>
            </contact>
            <friction>
              <ode/>
            </friction>
            <bounce/>
          </surface>
        </collision>
        <enable_wind>false</enable_wind>
      </link>
      <joint name='rotor_3_joint' type='revolute'>
        <parent>base_link</parent>
        <child>rotor_3</child>
        <axis>
          <xyz>0 0 1</xyz>
          <limit>
            <lower>-10000000000000000</lower>
            <upper>10000000000000000</upper>
            <effort>inf</effort>
            <velocity>inf</velocity>
            <stiffness>100000000</stiffness>
            <dissipation>1</dissipation>
          </limit>
          <dynamics>
            <spring_reference>0</spring_reference>
            <spring_stiffness>0</spring_stiffness>
            <damping>0</damping>
            <friction>0</friction>
          </dynamics>
        </axis>
        <pose>0 0 0 0 0 0</pose>
      </joint>
      <plugin name='ignition::gazebo::systems::MulticopterMotorModel' filename='ignition-gazebo-multicopter-motor-model-system'>
        <jointName>rotor_0_joint</jointName>
        <linkName>rotor_0</linkName>
        <turningDirection>ccw</turningDirection>
        <timeConstantUp>0.0125</timeConstantUp>
        <timeConstantDown>0.025</timeConstantDown>
        <maxRotVelocity>1000.0</maxRotVelocity>
        <motorConstant>8.54858e-06</motorConstant>
        <momentConstant>0.016</momentConstant>
        <commandSubTopic>command/motor_speed</commandSubTopic>
        <motorNumber>0</motorNumber>
        <rotorDragCoefficient>8.06428e-05</rotorDragCoefficient>
        <rollingMomentCoefficient>1e-06</rollingMomentCoefficient>
        <rotorVelocitySlowdownSim>10</rotorVelocitySlowdownSim>
        <motorType>velocity</motorType>
      </plugin>
      <plugin name='ignition::gazebo::systems::MulticopterMotorModel' filename='ignition-gazebo-multicopter-motor-model-system'>
        <jointName>rotor_1_joint</jointName>
        <linkName>rotor_1</linkName>
        <turningDirection>ccw</turningDirection>
        <timeConstantUp>0.0125</timeConstantUp>
        <timeConstantDown>0.025</timeConstantDown>
        <maxRotVelocity>1000.0</maxRotVelocity>
        <motorConstant>8.54858e-06</motorConstant>
        <momentConstant>0.016</momentConstant>
        <commandSubTopic>command/motor_speed</commandSubTopic>
        <motorNumber>1</motorNumber>
        <rotorDragCoefficient>8.06428e-05</rotorDragCoefficient>
        <rollingMomentCoefficient>1e-06</rollingMomentCoefficient>
        <rotorVelocitySlowdownSim>10</rotorVelocitySlowdownSim>
        <motorType>velocity</motorType>
      </plugin>
      <plugin name='ignition::gazebo::systems::MulticopterMotorModel' filename='ignition-gazebo-multicopter-motor-model-system'>
        <jointName>rotor_2_joint</jointName>
        <linkName>rotor_2</linkName>
        <turningDirection>cw</turningDirection>
        <timeConstantUp>0.0125</timeConstantUp>
        <timeConstantDown>0.025</timeConstantDown>
        <maxRotVelocity>1000.0</maxRotVelocity>
        <motorConstant>8.54858e-06</motorConstant>
        <momentConstant>0.016</momentConstant>
        <commandSubTopic>command/motor_speed</commandSubTopic>
        <motorNumber>2</motorNumber>
        <rotorDragCoefficient>8.06428e-05</rotorDragCoefficient>
        <rollingMomentCoefficient>1e-06</rollingMomentCoefficient>
        <rotorVelocitySlowdownSim>10</rotorVelocitySlowdownSim>
        <motorType>velocity</motorType>
      </plugin>
      <plugin name='ignition::gazebo::systems::MulticopterMotorModel' filename='ignition-gazebo-multicopter-motor-model-system'>
        <jointName>rotor_3_joint</jointName>
        <linkName>rotor_3</linkName>
        <turningDirection>cw</turningDirection>
        <timeConstantUp>0.0125</timeConstantUp>
        <timeConstantDown>0.025</timeConstantDown>
        <maxRotVelocity>1000.0</maxRotVelocity>
        <motorConstant>8.54858e-06</motorConstant>
        <momentConstant>0.016</momentConstant>
        <commandSubTopic>command/motor_speed</commandSubTopic>
        <motorNumber>3</motorNumber>
        <rotorDragCoefficient>8.06428e-05</rotorDragCoefficient>
        <rollingMomentCoefficient>1e-06</rollingMomentCoefficient>
        <rotorVelocitySlowdownSim>10</rotorVelocitySlowdownSim>
        <motorType>velocity</motorType>
      </plugin>
    </model>
    <light name='sun' type='directional'>
      <pose>0 0 10 0 0 0</pose>
      <cast_shadows>true</cast_shadows>
      <intensity>1</intensity>
      <direction>-0.5 0.10000000000000001 -0.90000000000000002</direction>
      <diffuse>0.800000012 0.800000012 0.800000012 1</diffuse>
      <specular>0.200000003 0.200000003 0.200000003 1</specular>
      <attenuation>
        <range>1000</range>
        <linear>0.01</linear>
        <constant>0.90000000000000002</constant>
        <quadratic>0.001</quadratic>
      </attenuation>
      <spot>
        <inner_angle>0</inner_angle>
        <outer_angle>0</outer_angle>
        <falloff>0</falloff>
      </spot>
    </light>
  </world>
</sdf>
